---
layout:     post
title:      Python自定义异常类
subtitle:   Python抛出一个自定义异常类
date:       2020-5-16
author:     xiaomaike
header-img: img/post-bg-python.jpg
catalog: true
tags:
    - Python
---

### 继承父类  Exception

```python

# 	自定义一个 异常类
class MyException(Exception):
    def __init__(self, fileName, reason):
        self.fileName = fileName
        self.reason = reason
        
            
def func1():
    try: #  尝试打开该文件
        file = open(fileName, 'r', encoding='utf-8')
        str_output = file.read() # 相关业务操作
        file.close()
    except:
        try:
        	raise MyException(fileName, '该文件不存在') #抛出一个实例化的 自定义异常类 (传递相关参数)
        finally: #  如果有没有该文件, 最后创建该文件
        print('该文件不存在，创建该新文件')
        file = open(fileName, 'a', encoding='utf-8')
        file.write(str_input)
        file.close()

if __name__ == "__main__":
	func1()
        
```



### 注意：

**try语句块的任何一条语句抛出异常时，后面的语句将不再执行，此时的控制权已经移交给except语句块。**

但在一些特殊情况下，这样的处理方式会存在一些问题，例如在一段打开文件并写入数据到文件的代码中，对文件的打开、写入、关闭等操作代码都放置在try语句块中，当执行写入文件的操作抛出异常时，后面关闭文件的语句将不会被执行，从而导致一些系统资源不能被及时释放。在这样的情况下，可以使用finally子句来解决这些问题